Workbook
Name Slicer_Category_Groups: #N/A
Name Slicer_MMM_YYY: #N/A
Name Slicer_Sales_person: #N/A
Name Slicer_Channel: #N/A
Name Slicer_Country: #N/A

Sheet Brief
A1: Assignment
A2: Excel Mastery Assignment: Sales Operations & Analytics | AD2: {=Region&" 'Brief'!A26 "&Country&" | "&City} -> #NAME?
A4: Overview:
A5: You are an analyst for a multi-regional electronics distributor. The 'Data' sheet contains 632 rows and 15 columns of transactional data with intentional data-quality issues.
A6: Your job is to clean, enrich, analyze, and present insights via a dynamic dashboard.
A8: Part A — Data Cleaning & Preparation:
A9: 1) Create a staging table where you:
A10: • Remove exact duplicate rows (define and document your duplicate criteria).
A11: • Fix data types (dates as Dates, numeric fields as numbers).
A12: • Handle missing values for City, Salesperson, and Channel using reasonable business logic (document your approach).
A13: • Flag and correct suspicious UnitPrice values (e.g., negative prices) and discounts (e.g., > 30%).
A14: • Ensure RequiredDate is not earlier than OrderDate; where it is, impute a corrected RequiredDate (explain your rule).
A15: • Add a derived 'LeadTimeDays' = RequiredDate − OrderDate (in days).
A17: 2) Create calculated columns (do these in Excel, not by formula in the data source):
... A67: 15) Ensure your dashboard responds to slicers without broken references.

Sheet READ ME
A1: READ ME : SALES ANALYSIS PROJECT
A3: Project Overview
A4: This project analyzes transactional sales data from a multi-regional electronics distributor. The dataset contains 632 rows and 15 columns, with intentional data quality issues.
A5: The objective was to:
A6: Clean and prepare the dataset
A7: Perform analytical tasks to generate business insights
A8: Build a scenario model to simulate business decisions
A9: Present findings in a structured and interpretable format
A12: Data issues identified
A13: The dataset contained several inconsistencies and quality issues:
A14: Duplicate records within the dataset
A15: Missing values in City, Salesperson, and Channel fields
... A130: Capability to present findings in a structured format

Sheet Data
A1: OrderID | B1: OrderDate | C1: RequiredDate | D1: Region | E1: Country | F1: City | G1: CustomerSegment | H1: Channel | I1: Salesperson | J1: ProductCategory | K1: SKU | L1: UnitCost | M1: UnitPrice | N1: DiscountPct | O1: Quantity
A2: ORD-2024-275203 | B2: 45362 | C2: 45388 | D2: Africa | E2: Kenya | F2: Kisumu | G2: Corporate | H2: Retail | I2: C. Otieno | J2: Components | K2: CMP-8270 | L2: 279.24 | M2: 608.9 | N2: 0.112 | O2: 9
A3: ORD-2024-358795 | B3: 45588 | C3: 45587 | D3: Africa | E3: Nigeria | F3: Port Harcourt | G3: Education | H3: Online | I3: J. Njeri | J3: Printers | K3: PRN-9322 | L3: 1084.39 | M3: 759.33 | N3: 0.237 | O3: 31
A4: ORD-2023-373538 | B4: 44985 | C4: 45010 | D4: Africa | E4: Kenya | F4: Nairobi | G4: Corporate | H4: Retail | I4: I. Johnson | J4: Networking | K4: NET-9666 | L4: 1460.76 | M4: -30.66 | N4: 0.131 | O4: 12
A5: ORD-2025-168148 | B5: 45745 | C5: 45749 | D5: Africa | E5: Nigeria | F5: Lagos | G5: Non-Profit | H5: Marketplace | I5: G. Dubois | J5: Phones | K5: PHN-4556 | L5: 259.93 | M5: 255.94 | N5: 0.072 | O5: 22
A6: ORD-2023-824839 | B6: 45266 | C6: 45291 | D6: Asia | E6: Japan | F6: Osaka | G6: Consumer | H6: Retail | I6: L. Okafor | J6: Printers | K6: PRN-8041 | L6: 663.03 | M6: 813.51 | N6: 0.102 | O6: 15
A7: ORD-2023-723587 | B7: 44928 | C7: 44931 | D7: Americas | E7: Canada | F7: Toronto | G7: Corporate | H7: Distributor | I7: B. Chen | J7: Laptops | K7: LAP-8555 | L7: 315.87 | M7: 591.68 | N7: 0 | O7: 7
A8: ORD-2024-336584 | B8: 45653 | C8: 45671 | D8: Asia | E8: India | F8: Bengaluru | G8: Small Business | H8: Marketplace | I8: E. Garcia | J8: Monitors | K8: MON-8629 | L8: 586.07 | M8: 845.97 | N8: 0.147 | O8: 4
A9: ORD-2023-112666 | B9: 44941 | C9: 44939 | D9: Africa | E9: Nigeria | F9: Abuja | G9: Education | H9: Online | I9: O. Wang | J9: Printers | K9: PRN-6276 | L9: 28.38 | M9: 47.22 | N9: 0.194 | O9: 18
A10: ORD-2024-589570 | B10: 45416 | C10: 45441 | D10: Africa | E10: Nigeria | F10: Abuja | G10: Non-Profit | H10: Marketplace | I10: O. Wang | J10: Monitors | K10: MON-6892 | L10: 1295.34 | M10: 2530.81 | N10: 0.031 | O10: 6
A11: ORD-2025-997421 | B11: 45798 | C11: 45817 | D11: Americas | E11: Brazil | F11: São Paulo | G11: Non-Profit | H11: Online | I11: A. Patel | J11: Components | K11: CMP-3731 | L11: 1331.38 | M11: 2309.56 | N11: 0.149 | O11: 31
A12: ORD-2024-210687 | B12: 45319 | C12: 45331 | D12: Europe | E12: Germany | F12: Berlin | G12: Corporate | H12: Online | I12: G. Dubois | J12: Accessories | K12: ACC-7938 | L12: 644.17 | M12: 700.12 | N12: 0.006 | O12: 23
A13: ORD-2025-515515 | B13: 45660 | C13: 45680 | D13: Asia | E13: Japan | F13: Osaka | G13: Corporate | H13: Distributor | I13: F. Müller | J13: Phones | K13: PHN-7019 | L13: 908.6 | M13: 691.37 | N13: 0.25 | O13: 20
... A34: ORD-2025-474710 | B34: 45862 | C34: 45875 | D34: Africa | E34: South Africa | F34: Johannesburg | G34: Education | H34: Marketplace | I34: D. Smith | J34: Networking | K34: NET-7966 | L34: 1463.9 | M34: 2633.02 | N34: 0.084 | O34: 4
A35: ORD-2024-629525 | B35: 45400 | C35: 45420 | D35: Europe | E35: United Kingdom | F35: London | G35: Non-Profit | I35: D. Smith | J35: Laptops | K35: LAP-9932 | L35: 645.33 | M35: 1321.85 | N35: 0 | O35: 10
A36: ORD-2024-167215 | B36: 45527 | C36: 45525 | D36: Africa | E36: South Africa | F36: Johannesburg | G36: Education | H36: Retail | I36: E. Garcia | J36: Components | K36: CMP-1559 | L36: 1432.52 | M36: 3036.87 | N36: 0 | O36: 9
A37: ORD-2023-864121 | B37: 45012 | C37: 45038 | D37: Asia | E37: India | F37: Delhi | G37: Non-Profit | H37: Marketplace | I37: J. Njeri | J37: Printers | K37: PRN-4506 | L37: 178.53 | M37: 199.37 | N37: 0.101 | O37: 37
A38: ORD-2024-692673 | B38: 45358 | C38: 45376 | D38: Europe | E38: Germany | F38: Munich | G38: Corporate | H38: Online | I38: B. Chen | J38: Components | K38: CMP-7617 | L38: 712.84 | M38: 927.51 | N38: 0.243 | O38: 27
A39: ORD-2025-718992 | B39: 45832 | C39: 45848 | D39: Asia | E39: China | F39: Shanghai | G39: Enterprise | H39: Direct | I39: N. Brown | J39: Components | K39: CMP-8390 | L39: 757.19 | M39: 1735.41 | N39: 0.136 | O39: 8
A40: ORD-2024-599522 | B40: 45401 | C40: 45418 | D40: Africa | E40: Nigeria | F40: Port Harcourt | G40: Non-Profit | H40: Online | I40: A. Patel | J40: Printers | K40: PRN-7303 | L40: 865.33 | M40: 1395.64 | N40: 0.175 | O40: 13
A41: ORD-2023-651638 | B41: 45094 | C41: 45101 | D41: Americas | E41: USA | F41: San Francisco | G41: Corporate | H41: Retail | I41: I. Johnson | J41: Printers | K41: PRN-6536 | L41: 313.99 | M41: 454.42 | N41: 0.129 | O41: 9
A42: ORD-2024-635626 | B42: 45531 | C42: 45554 | D42: Europe | E42: Germany | F42: Berlin | G42: Small Business | H42: Direct | I42: D. Smith | J42: Monitors | K42: MON-9967 | L42: 1024.01 | M42: 1580.97 | N42: 0.037 | O42: 27
A43: ORD-2024-296582 | B43: 45302 | C43: 45324 | D43: Africa | E43: South Africa | F43: Durban | G43: Consumer | H43: Online | I43: K. Singh | J43: Networking | K43: NET-1412 | L43: 1206.2 | M43: 1759.79 | N43: 0 | O43: 6
A44: ORD-2024-998320 | B44: 45590 | C44: 45610 | D44: Africa | E44: Kenya | F44: Mombasa | G44: Corporate | H44: Direct | I44: H. Kim | J44: Printers | K44: PRN-3143 | L44: 1396.48 | M44: 3204.5 | N44: 0.318 | O44: 14
A45: ORD-2025-820255 | B45: 45806 | C45: 45828 | D45: Europe | E45: Germany | F45: Berlin | G45: Corporate | H45: Direct | I45: A. Patel | J45: Printers | K45: PRN-9787 | L45: 483.47 | M45: 1135.43 | N45: 0.146 | O45: 11
A46: ORD-2024-389336 | B46: 45432 | C46: 45445 | D46: Americas | E46: Canada | F46: Vancouver | G46: Enterprise | H46: Marketplace | I46: K. Singh | J46: Components | K46: CMP-5946 | L46: 675.43 | M46: 996.36 | N46: 0.182 | O46: 22
A47: ORD-2023-308124 | B47: 45035 | C47: 45046 | D47: Asia | E47: India | F47: Delhi | G47: Small Business | H47: Retail | I47: A. Patel | J47: Networking | K47: NET-2062 | L47: 826.55 | M47: 1397.05 | N47: 0.169 | O47: 28
... A77: ORD-2023-722117 | B77: 45187 | C77: 45207 | D77: Asia | E77: India | F77: Delhi | G77: Small Business | H77: Direct | I77: B. Chen | J77: Components | K77: CMP-1009 | L77: 825.64 | M77: 1108.43 | N77: 0.114 | O77: 7
A78: ORD-2024-446699 | B78: 45532 | C78: 45560 | D78: Americas | E78: Brazil | F78: Rio de Janeiro | G78: Non-Profit | H78: Online | J78: Accessories | K78: ACC-4490 | L78: 1394.65 | M78: 3144.1 | N78: 0.134 | O78: 13
A79: ORD-2024-451005 | B79: 45473 | C79: 45471 | D79: Americas | E79: Brazil | F79: Rio de Janeiro | G79: Small Business | H79: Direct | I79: L. Okafor | J79: Accessories | K79: ACC-9162 | L79: 1112.98 | M79: 2095.73 | N79: 0.072 | O79: 17
A80: ORD-2023-290279 | B80: 45091 | C80: 45093 | D80: Europe | E80: United Kingdom | F80: Manchester | G80: Non-Profit | H80: Direct | I80: K. Singh | J80: Components | K80: CMP-5820 | L80: 357.36 | M80: 703.62 | N80: 0.257 | O80: 20
A81: ORD-2024-192263 | B81: 45617 | C81: 45647 | D81: Europe | E81: France | F81: Marseille | G81: Small Business | H81: Direct | I81: I. Johnson | J81: Monitors | K81: MON-7943 | L81: 1122.68 | M81: 1997.19 | N81: 0.186 | O81: 3
A82: ORD-2023-159379 | B82: 44965 | C82: 44968 | D82: Africa | E82: South Africa | F82: Cape Town | G82: Corporate | H82: Direct | I82: M. Rossi | J82: Networking | K82: NET-5018 | L82: 1410.05 | M82: 2763.95 | N82: 0.161 | O82: 26
A83: ORD-2023-343322 | B83: 45157 | C83: 45181 | D83: Americas | E83: Canada | F83: Vancouver | G83: Enterprise | H83: Retail | I83: I. Johnson | J83: Printers | K83: PRN-9669 | L83: 1183.95 | M83: 1503.53 | N83: 0.241 | O83: 16
A84: ORD-2025-114382 | B84: 45791 | C84: 45801 | D84: Europe | E84: France | F84: Paris | G84: Small Business | H84: Marketplace | I84: K. Singh | J84: Components | K84: CMP-2865 | L84: 170.39 | M84: 388.04 | N84: 0.084 | O84: 15
A85: ORD-2025-488349 | B85: 45770 | C85: 45769 | D85: Americas | E85: USA | F85: San Francisco | G85: Non-Profit | H85: Distributor | I85: D. Smith | J85: Monitors | K85: MON-3371 | L85: 23.24 | M85: 44.57 | N85: 0.215 | O85: 15
A86: ORD-2025-330203 | B86: 45741 | C86: 45764 | D86: Europe | E86: United Kingdom | F86: London | G86: Consumer | H86: Retail | I86: H. Kim | J86: Networking | K86: NET-7166 | L86: 1421.19 | M86: 1808.26 | N86: 0.104 | O86: 13
A87: ORD-2023-841426 | B87: 45282 | C87: 45283 | D87: Africa | E87: South Africa | F87: Cape Town | G87: Non-Profit | H87: Marketplace | I87: D. Smith | J87: Components | K87: CMP-4531 | L87: 1186.18 | M87: 1285.09 | N87: 0.07 | O87: 11
A88: ORD-2024-594592 | B88: 45388 | C88: 45407 | D88: Asia | E88: China | F88: Shanghai | G88: Corporate | H88: Retail | I88: K. Singh | J88: Components | K88: CMP-8196 | L88: 1366.48 | M88: 1678.14 | N88: 0.154 | O88: 10
A89: ORD-2025-863978 | B89: 45876 | C89: 45888 | D89: Africa | E89: Kenya | F89: Nakuru | G89: Corporate | I89: M. Rossi | J89: Components | K89: CMP-2854 | L89: 601.51 | M89: 679.35 | N89: 0.188 | O89: 3
...

Sheet Staging Data
A1: Order ID | B1: Order Date | C1: Required Date | D1: Region | E1: Country | F1: City | G1: Customer Segment | H1: Channel | I1: Sales person | J1: Product Category | K1: SKU | L1: UnitCost | M1: Unit Price | N1: Discount % | O1: Quantity | P1: Negative prices | Q1: Clean Unit Prices | R1: Discounts >30% | S1: Clean discounts | T1: Date Diff | U1: Validated Required date | V1: Lead Time days | W1: Gross Revenue | X1: Cost of Goods | Y1: Gross Profit | Z1: Margin % | AA1: MMM-YYY | AB1: Quarters | AC1: Region Hierarchy | AD1: Category Groups | AE1: Price Band | AF1: Clean country | AG1: Country start Date | AH1: Country Start Month | AI1: Order Month date | AJ1: On Time Flag | AK1: Flagged Discount % | AL1: What-if Discount | AM1: What if Cost | AN1: What If Quantity | AO1: What if Revenue | AP1: What if Profit
A2: ORD-2024-275203 | B2: 45362 | C2: 45388 | D2: Africa | E2: Kenya | F2: Kisumu | G2: Corporate | H2: Retail | I2: C. Otieno | J2: Components | K2: CMP-8270 | L2: 279.24 | M2: 608.9 | N2: 0.112 | O2: 9 | P2: =IF(M2>0,"Valid") -> Valid | Q2: =ABS(M2) -> 608.9 | R2: =IF(N2>30%,"Excess") -> FALSE | S2: =IF(R2="Excess",30%,N2) -> 0.112 | T2: =(C2-B2) -> 26 | U2: =IF(C2<B2,B2+7,C2) -> 45388 | V2: =(U2-B2) -> 26 | W2: =(Q2*O2*(100-S2)) -> 547396.23 | X2: =(Q2*O2) -> 5480.1 | Y2: =W2-X2 -> 541916.13 | Z2: =Y2/W2 -> 0.98998879 | AA2: Mar-2024 | AB2: ="Q"&ROUNDUP(MONTH(B2)/3,0)&"-"&YEAR(B2) -> Q1-2024 | AC2: =D2&" → "&E2&" → "&F2 -> Africa → Kenya → Kisumu | AD2: =IF(OR(J2="Laptops",J2="Phones"),"Devices",IF(OR(J2="Monitors",J2="Printers"),"Peripherals","Support")) -> Support | AE2: =IF(B2<=PERCENTILE($B$2:$B$632,0.33),"Low",IF(B2<=PERCENTILE($B$2:$B$632,0.66),"Medium","High")) -> Medium | AF2: =UPPER(TRIM(CLEAN(SUBSTITUTE(E2,CHAR(160),"")))) -> KENYA | AG2: =_xlfn.MINIFS($B$2:$B$633,$AF$2:$AF$633,AF2) -> 44946 | AH2: =TEXT(AG2,"MMM-YYYY") -> Jan-2023 | AI2: =EOMONTH(B2,0) -> 45382 | AJ2: =IF(V2<=7,1,0) -> 0 | AK2: =IF(N2>20%,1,0) -> 0 | AL2: =MIN(N2,'Scenario Modelling'!$B$2) -> 0.112 | AM2: =L2*(1+'Scenario Modelling'!$B$3) -> 321.126 | AN2: =O2*(1+'Scenario Modelling'!$B$4) -> 10.8 | AO2: =AN2*M2*(1-AL2) -> 5839.5946 | AP2: =(M2*(1-AL2)-AM2)*AN2 -> 2371.4338
A3: ORD-2024-358795 | B3: 45588 | C3: 45587 | D3: Africa | E3: Nigeria | F3: Port Harcourt | G3: Education | H3: Online | I3: J. Njeri | J3: Printers | K3: PRN-9322 | L3: 1084.39 | M3: 759.33 | N3: 0.237 | O3: 31 | P3: =IF(M3>0,"Valid") -> Valid | Q3: =ABS(M3) -> 759.33 | R3: =IF(N3>30%,"Excess") -> FALSE | S3: =IF(R3="Excess",30%,N3) -> 0.237 | T3: =(C3-B3) -> -1 | U3: =IF(C3<B3,B3+7,C3) -> 45595 | V3: =(U3-B3) -> 7 | W3: =(Q3*O3*(100-S3)) -> 2348344.2 | X3: =(Q3*O3) -> 23539.23 | Y3: =W3-X3 -> 2324805 | Z3: =Y3/W3 -> 0.98997624 | AA3: Oct-2024 | AB3: ="Q"&ROUNDUP(MONTH(B3)/3,0)&"-"&YEAR(B3) -> Q4-2024 | AC3: =D3&" → "&E3&" → "&F3 -> Africa → Nigeria → Port Harcourt | AD3: =IF(OR(J3="Laptops",J3="Phones"),"Devices",IF(OR(J3="Monitors",J3="Printers"),"Peripherals","Support")) -> Peripherals | AE3: =IF(B3<=PERCENTILE($B$2:$B$632,0.33),"Low",IF(B3<=PERCENTILE($B$2:$B$632,0.66),"Medium","High")) -> Medium | AF3: =UPPER(TRIM(CLEAN(SUBSTITUTE(E3,CHAR(160),"")))) -> NIGERIA | AG3: =_xlfn.MINIFS($B$2:$B$633,$AF$2:$AF$633,AF3) -> 44941 | AH3: =TEXT(AG3,"MMM-YYYY") -> Jan-2023 | AI3: =EOMONTH(B3,0) -> 45596 | AJ3: =IF(V3<=7,1,0) -> 1 | AK3: =IF(N3>20%,1,0) -> 1 | AL3: =MIN(N3,'Scenario Modelling'!$B$2) -> 0.237 | AM3: =L3*(1+'Scenario Modelling'!$B$3) -> 1247.0485 | AN3: =O3*(1+'Scenario Modelling'!$B$4) -> 37.2 | AO3: =AN3*M3*(1-AL3) -> 21552.519 | AP3: =(M3*(1-AL3)-AM3)*AN3 -> -24837.685
A4: ORD-2023-373538 | B4: 44985 | C4: 45010 | D4: Africa | E4: Kenya | F4: Nairobi | G4: Corporate | H4: Retail | I4: I. Johnson | J4: Networking | K4: NET-9666 | L4: 1460.76 | M4: -30.66 | N4: 0.131 | O4: 12 | P4: =IF(M4>0,"Valid") -> FALSE | Q4: =ABS(M4) -> 30.66 | R4: =IF(N4>30%,"Excess") -> FALSE | S4: =IF(R4="Excess",30%,N4) -> 0.131 | T4: =(C4-B4) -> 25 | U4: =IF(C4<B4,B4+7,C4) -> 45010 | V4: =(U4-B4) -> 25 | W4: =(Q4*O4*(100-S4)) -> 36743.802 | X4: =(Q4*O4) -> 367.92 | Y4: =W4-X4 -> 36375.882 | Z4: =Y4/W4 -> 0.98998688 | AA4: Feb-2023 | AB4: ="Q"&ROUNDUP(MONTH(B4)/3,0)&"-"&YEAR(B4) -> Q1-2023 | AC4: =D4&" → "&E4&" → "&F4 -> Africa → Kenya → Nairobi | AD4: =IF(OR(J4="Laptops",J4="Phones"),"Devices",IF(OR(J4="Monitors",J4="Printers"),"Peripherals","Support")) -> Support | AE4: =IF(B4<=PERCENTILE($B$2:$B$632,0.33),"Low",IF(B4<=PERCENTILE($B$2:$B$632,0.66),"Medium","High")) -> Low | AF4: =UPPER(TRIM(CLEAN(SUBSTITUTE(E4,CHAR(160),"")))) -> KENYA | AG4: 44946 | AH4: =TEXT(AG4,"MMM-YYYY") -> Jan-2023 | AI4: =EOMONTH(B4,0) -> 44985 | AJ4: =IF(V4<=7,1,0) -> 0 | AK4: =IF(N4>20%,1,0) -> 0 | AL4: =MIN(N4,'Scenario Modelling'!$B$2) -> 0.131 | AM4: =L4*(1+'Scenario Modelling'!$B$3) -> 1679.874 | AN4: =O4*(1+'Scenario Modelling'!$B$4) -> 14.4 | AO4: =AN4*M4*(1-AL4) -> -383.66698 | AP4: =(M4*(1-AL4)-AM4)*AN4 -> -24573.853
A5: ORD-2025-168148 | B5: 45745 | C5: 45749 | D5: Africa | E5: Nigeria | F5: Lagos | G5: Non-Profit | H5: Marketplace | I5: G. Dubois | J5: Phones | K5: PHN-4556 | L5: 259.93 | M5: 255.94 | N5: 0.072 | O5: 22 | P5: =IF(M5>0,"Valid") -> Valid | Q5: =ABS(M5) -> 255.94 | R5: =IF(N5>30%,"Excess") -> FALSE | S5: =IF(R5="Excess",30%,N5) -> 0.072 | T5: =(C5-B5) -> 4 | U5: =IF(C5<B5,B5+7,C5) -> 45749 | V5: =(U5-B5) -> 4 | W5: =(Q5*O5*(100-S5)) -> 562662.59 | X5: =(Q5*O5) -> 5630.68 | Y5: =W5-X5 -> 557031.91 | Z5: =Y5/W5 -> 0.98999279 | AA5: Mar-2025 | AB5: ="Q"&ROUNDUP(MONTH(B5)/3,0)&"-"&YEAR(B5) -> Q1-2025 | AC5: =D5&" → "&E5&" → "&F5 -> Africa → Nigeria → Lagos | AD5: =IF(OR(J5="Laptops",J5="Phones"),"Devices",IF(OR(J5="Monitors",J5="Printers"),"Peripherals","Support")) -> Devices | AE5: =IF(B5<=PERCENTILE($B$2:$B$632,0.33),"Low",IF(B5<=PERCENTILE($B$2:$B$632,0.66),"Medium","High")) -> High | AF5: =UPPER(TRIM(CLEAN(SUBSTITUTE(E5,CHAR(160),"")))) -> NIGERIA | AG5: =_xlfn.MINIFS($B$2:$B$633,$AF$2:$AF$633,AF5) -> 44941 | AH5: =TEXT(AG5,"MMM-YYYY") -> Jan-2023 | AI5: =EOMONTH(B5,0) -> 45747 | AJ5: =IF(V5<=7,1,0) -> 1 | AK5: =IF(N5>20%,1,0) -> 0 | AL5: =MIN(N5,'Scenario Modelling'!$B$2) -> 0.072 | AM5: =L5*(1+'Scenario Modelling'!$B$3) -> 298.9195 | AN5: =O5*(1+'Scenario Modelling'!$B$4) -> 26.4 | AO5: =AN5*M5*(1-AL5) -> 6270.3252 | AP5: =(M5*(1-AL5)-AM5)*AN5 -> -1621.1496
A6: ORD-2023-723587 | B6: 44928 | C6: 44931 | D6: Americas | E6: Canada | F6: Toronto | G6: Corporate | H6: Distributor | I6: B. Chen | J6: Laptops | K6: LAP-8555 | L6: 315.87 | M6: 591.68 | N6: 0 | O6: 7 | P6: =IF(M6>0,"Valid") -> Valid | Q6: =ABS(M6) -> 591.68 | R6: =IF(N6>30%,"Excess") -> FALSE | S6: =IF(R6="Excess",30%,N6) -> 0 | T6: =(C6-B6) -> 3 | U6: =IF(C6<B6,B6+7,C6) -> 44931 | V6: =(U6-B6) -> 3 | W6: =(Q6*O6*(100-S6)) -> 414176 | X6: =(Q6*O6) -> 4141.76 | Y6: =W6-X6 -> 410034.24 | Z6: =Y6/W6 -> 0.99 | AA6: Jan-2023 | AB6: ="Q"&ROUNDUP(MONTH(B6)/3,0)&"-"&YEAR(B6) -> Q1-2023 | AC6: =D6&" → "&E6&" → "&F6 -> Americas → Canada → Toronto | AD6: =IF(OR(J6="Laptops",J6="Phones"),"Devices",IF(OR(J6="Monitors",J6="Printers"),"Peripherals","Support")) -> Devices | AE6: =IF(B6<=PERCENTILE($B$2:$B$632,0.33),"Low",IF(B6<=PERCENTILE($B$2:$B$632,0.66),"Medium","High")) -> Low | AF6: =UPPER(TRIM(CLEAN(SUBSTITUTE(E6,CHAR(160),"")))) -> CANADA | AG6: =_xlfn.MINIFS($B$2:$B$633,$AF$2:$AF$633,AF6) -> 44928 | AH6: =TEXT(AG6,"MMM-YYYY") -> Jan-2023 | AI6: =EOMONTH(B6,0) -> 44957 | AJ6: =IF(V6<=7,1,0) -> 1 | AK6: =IF(N6>20%,1,0) -> 0 | AL6: =MIN(N6,'Scenario Modelling'!$B$2) -> 0 | AM6: =L6*(1+'Scenario Modelling'!$B$3) -> 363.2505 | AN6: =O6*(1+'Scenario Modelling'!$B$4) -> 8.4 | AO6: =AN6*M6*(1-AL6) -> 4970.112 | AP6: =(M6*(1-AL6)-AM6)*AN6 -> 1918.8078
A7: ORD-2024-336584 | B7: 45653 | C7: 45671 | D7: Asia | E7: India | F7: Bengaluru | G7: Small Business | H7: Marketplace | I7: E. Garcia | J7: Monitors | K7: MON-8629 | L7: 586.07 | M7: 845.97 | N7: 0.147 | O7: 4 | P7: =IF(M7>0,"Valid") -> Valid | Q7: =ABS(M7) -> 845.97 | R7: =IF(N7>30%,"Excess") -> FALSE | S7: =IF(R7="Excess",30%,N7) -> 0.147 | T7: =(C7-B7) -> 18 | U7: =IF(C7<B7,B7+7,C7) -> 45671 | V7: =(U7-B7) -> 18 | W7: =(Q7*O7*(100-S7)) -> 337890.57 | X7: =(Q7*O7) -> 3383.88 | Y7: =W7-X7 -> 334506.69 | Z7: =Y7/W7 -> 0.98998528 | AA7: Dec-2024 | AB7: ="Q"&ROUNDUP(MONTH(B7)/3,0)&"-"&YEAR(B7) -> Q4-2024 | AC7: =D7&" → "&E7&" → "&F7 -> Asia → India → Bengaluru | AD7: =IF(OR(J7="Laptops",J7="Phones"),"Devices",IF(OR(J7="Monitors",J7="Printers"),"Peripherals","Support")) -> Peripherals | AE7: =IF(B7<=PERCENTILE($B$2:$B$632,0.33),"Low",IF(B7<=PERCENTILE($B$2:$B$632,0.66),"Medium","High")) -> High | AF7: =UPPER(TRIM(CLEAN(SUBSTITUTE(E7,CHAR(160),"")))) -> INDIA | AG7: 44955 | AH7: =TEXT(AG7,"MMM-YYYY") -> Jan-2023 | AI7: =EOMONTH(B7,0) -> 45657 | AJ7: =IF(V7<=7,1,0) -> 0 | AK7: =IF(N7>20%,1,0) -> 0 | AL7: =MIN(N7,'Scenario Modelling'!$B$2) -> 0.147 | AM7: =L7*(1+'Scenario Modelling'!$B$3) -> 673.9805 | AN7: =O7*(1+'Scenario Modelling'!$B$4) -> 4.8 | AO7: =AN7*M7*(1-AL7) -> 3463.7396 | AP7: =(M7*(1-AL7)-AM7)*AN7 -> 228.63317
A8: ORD-2023-112666 | B8: 44941 | C8: 44939 | D8: Africa | E8: Nigeria | F8: Abuja | G8: Education | H8: Online | I8: O. Wang | J8: Printers | K8: PRN-6276 | L8: 28.38 | M8: 47.22 | N8: 0.194 | O8: 18 | P8: =IF(M8>0,"Valid") -> Valid | Q8: =ABS(M8) -> 47.22 | R8: =IF(N8>30%,"Excess") -> FALSE | S8: =IF(R8="Excess",30%,N8) -> 0.194 | T8: =(C8-B8) -> -2 | U8: =IF(C8<B8,B8+7,C8) -> 44948 | V8: =(U8-B8) -> 7 | W8: =(Q8*O8*(100-S8)) -> 84831.108 | X8: =(Q8*O8) -> 849.96 | Y8: =W8-X8 -> 83981.148 | Z8: =Y8/W8 -> 0.98998056 | AA8: Jan-2023 | AB8: ="Q"&ROUNDUP(MONTH(B8)/3,0)&"-"&YEAR(B8) -> Q1-2023 | AC8: =D8&" → "&E8&" → "&F8 -> Africa → Nigeria → Abuja | AD8: =IF(OR(J8="Laptops",J8="Phones"),"Devices",IF(OR(J8="Monitors",J8="Printers"),"Peripherals","Support")) -> Peripherals | AE8: =IF(B8<=PERCENTILE($B$2:$B$632,0.33),"Low",IF(B8<=PERCENTILE($B$2:$B$632,0.66),"Medium","High")) -> Low | AF8: =UPPER(TRIM(CLEAN(SUBSTITUTE(E8,CHAR(160),"")))) -> NIGERIA | AG8: =_xlfn.MINIFS($B$2:$B$633,$AF$2:$AF$633,AF8) -> 44941 | AH8: =TEXT(AG8,"MMM-YYYY") -> Jan-2023 | AI8: =EOMONTH(B8,0) -> 44957 | AJ8: =IF(V8<=7,1,0) -> 1 | AK8: =IF(N8>20%,1,0) -> 0 | AL8: =MIN(N8,'Scenario Modelling'!$B$2) -> 0.194 | AM8: =L8*(1+'Scenario Modelling'!$B$3) -> 32.637 | AN8: =O8*(1+'Scenario Modelling'!$B$4) -> 21.6 | AO8: =AN8*M8*(1-AL8) -> 822.08131 | AP8: =(M8*(1-AL8)-AM8)*AN8 -> 117.12211
A9: ORD-2024-589570 | B9: 45416 | C9: 45441 | D9: Africa | E9: Nigeria | F9: Abuja | G9: Non-Profit | H9: Marketplace | I9: O. Wang | J9: Monitors | K9: MON-6892 | L9: 1295.34 | M9: 2530.81 | N9: 0.031 | O9: 6 | P9: =IF(M9>0,"Valid") -> Valid | Q9: =ABS(M9) -> 2530.81 | R9: =IF(N9>30%,"Excess") -> FALSE | S9: =IF(R9="Excess",30%,N9) -> 0.031 | T9: =(C9-B9) -> 25 | U9: =IF(C9<B9,B9+7,C9) -> 45441 | V9: =(U9-B9) -> 25 | W9: =(Q9*O9*(100-S9)) -> 1518015.3 | X9: =(Q9*O9) -> 15184.86 | Y9: =W9-X9 -> 1502830.4 | Z9: =Y9/W9 -> 0.9899969 | AA9: May-2024 | AB9: ="Q"&ROUNDUP(MONTH(B9)/3,0)&"-"&YEAR(B9) -> Q2-2024 | AC9: =D9&" → "&E9&" → "&F9 -> Africa → Nigeria → Abuja | AD9: =IF(OR(J9="Laptops",J9="Phones"),"Devices",IF(OR(J9="Monitors",J9="Printers"),"Peripherals","Support")) -> Peripherals | AE9: =IF(B9<=PERCENTILE($B$2:$B$632,0.33),"Low",IF(B9<=PERCENTILE($B$2:$B$632,0.66),"Medium","High")) -> Medium | AF9: =UPPER(TRIM(CLEAN(SUBSTITUTE(E9,CHAR(160),"")))) -> NIGERIA | AG9: =_xlfn.MINIFS($B$2:$B$633,$AF$2:$AF$633,AF9) -> 44941 | AH9: =TEXT(AG9,"MMM-YYYY") -> Jan-2023 | AI9: =EOMONTH(B9,0) -> 45443 | AJ9: =IF(V9<=7,1,0) -> 0 | AK9: =IF(N9>20%,1,0) -> 0 | AL9: =MIN(N9,'Scenario Modelling'!$B$2) -> 0.031 | AM9: =L9*(1+'Scenario Modelling'!$B$3) -> 1489.641 | AN9: =O9*(1+'Scenario Modelling'!$B$4) -> 7.2 | AO9: =AN9*M9*(1-AL9) -> 17656.955 | AP9: =(M9*(1-AL9)-AM9)*AN9 -> 6931.54
A10: ORD-2025-997421 | B10: 45798 | C10: 45817 | D10: Americas | E10: Brazil | F10: São Paulo | G10: Non-Profit | H10: Online | I10: A. Patel | J10: Components | K10: CMP-3731 | L10: 1331.38 | M10: 2309.56 | N10: 0.149 | O10: 31 | P10: =IF(M10>0,"Valid") -> Valid | Q10: =ABS(M10) -> 2309.56 | R10: =IF(N10>30%,"Excess") -> FALSE | S10: =IF(R10="Excess",30%,N10) -> 0.149 | T10: =(C10-B10) -> 19 | U10: =IF(C10<B10,B10+7,C10) -> 45817 | V10: =(U10-B10) -> 19 | W10: =(Q10*O10*(100-S10)) -> 7148968.1 | X10: =(Q10*O10) -> 71596.36 | Y10: =W10-X10 -> 7077371.8 | Z10: =Y10/W10 -> 0.98998508 | AA10: May-2025 | AB10: ="Q"&ROUNDUP(MONTH(B10)/3,0)&"-"&YEAR(B10) -> Q2-2025 | AC10: =D10&" → "&E10&" → "&F10 -> Americas → Brazil → São Paulo | AD10: =IF(OR(J10="Laptops",J10="Phones"),"Devices",IF(OR(J10="Monitors",J10="Printers"),"Peripherals","Support")) -> Support | AE10: =IF(B10<=PERCENTILE($B$2:$B$632,0.33),"Low",IF(B10<=PERCENTILE($B$2:$B$632,0.66),"Medium","High")) -> High | AF10: =UPPER(TRIM(CLEAN(SUBSTITUTE(E10,CHAR(160),"")))) -> BRAZIL | AG10: =_xlfn.MINIFS($B$2:$B$633,$AF$2:$AF$633,AF10) -> 44955 | AH10: =TEXT(AG10,"MMM-YYYY") -> Jan-2023 | AI10: =EOMONTH(B10,0) -> 45808 | AJ10: =IF(V10<=7,1,0) -> 0 | AK10: =IF(N10>20%,1,0) -> 0 | AL10: =MIN(N10,'Scenario Modelling'!$B$2) -> 0.149 | AM10: =L10*(1+'Scenario Modelling'!$B$3) -> 1531.087 | AN10: =O10*(1+'Scenario Modelling'!$B$4) -> 37.2 | AO10: =AN10*M10*(1-AL10) -> 73114.203 | AP10: =(M10*(1-AL10)-AM10)*AN10 -> 16157.766
A11: ORD-2024-210687 | B11: 45319 | C11: 45331 | D11: Europe | E11: Germany | F11: Berlin | G11: Corporate | H11: Online | I11: G. Dubois | J11: Accessories | K11: ACC-7938 | L11: 644.17 | M11: 700.12 | N11: 0.006 | O11: 23 | P11: =IF(M11>0,"Valid") -> Valid | Q11: =ABS(M11) -> 700.12 | R11: =IF(N11>30%,"Excess") -> FALSE | S11: =IF(R11="Excess",30%,N11) -> 0.006 | T11: =(C11-B11) -> 12 | U11: =IF(C11<B11,B11+7,C11) -> 45331 | V11: =(U11-B11) -> 12 | W11: =(Q11*O11*(100-S11)) -> 1610179.4 | X11: =(Q11*O11) -> 16102.76 | Y11: =W11-X11 -> 1594076.6 | Z11: =Y11/W11 -> 0.9899994 | AA11: Jan-2024 | AB11: ="Q"&ROUNDUP(MONTH(B11)/3,0)&"-"&YEAR(B11) -> Q1-2024 | AC11: =D11&" → "&E11&" → "&F11 -> Europe → Germany → Berlin | AD11: =IF(OR(J11="Laptops",J11="Phones"),"Devices",IF(OR(J11="Monitors",J11="Printers"),"Peripherals","Support")) -> Support | AE11: =IF(B11<=PERCENTILE($B$2:$B$632,0.33),"Low",IF(B11<=PERCENTILE($B$2:$B$632,0.66),"Medium","High")) -> Medium | AF11: =UPPER(TRIM(CLEAN(SUBSTITUTE(E11,CHAR(160),"")))) -> GERMANY | AG11: 44948 | AH11: =TEXT(AG11,"MMM-YYYY") -> Jan-2023 | AI11: =EOMONTH(B11,0) -> 45322 | AJ11: =IF(V11<=7,1,0) -> 0 | AK11: =IF(N11>20%,1,0) -> 0 | AL11: =MIN(N11,'Scenario Modelling'!$B$2) -> 0.006 | AM11: =L11*(1+'Scenario Modelling'!$B$3) -> 740.7955 | AN11: =O11*(1+'Scenario Modelling'!$B$4) -> 27.6 | AO11: =AN11*M11*(1-AL11) -> 19207.372 | AP11: =(M11*(1-AL11)-AM11)*AN11 -> -1238.5837
A12: ORD-2025-515515 | B12: 45660 | C12: 45680 | D12: Asia | E12: Japan | F12: Osaka | G12: Corporate | H12: Distributor | I12: F. Müller | J12: Phones | K12: PHN-7019 | L12: 908.6 | M12: 691.37 | N12: 0.25 | O12: 20 | P12: =IF(M12>0,"Valid") -> Valid | Q12: =ABS(M12) -> 691.37 | R12: =IF(N12>30%,"Excess") -> FALSE | S12: =IF(R12="Excess",30%,N12) -> 0.25 | T12: =(C12-B12) -> 20 | U12: =IF(C12<B12,B12+7,C12) -> 45680 | V12: =(U12-B12) -> 20 | W12: =(Q12*O12*(100-S12)) -> 1379283.1 | X12: =(Q12*O12) -> 13827.4 | Y12: =W12-X12 -> 1365455.8 | Z12: =Y12/W12 -> 0.98997494 | AA12: Jan-2025 | AB12: ="Q"&ROUNDUP(MONTH(B12)/3,0)&"-"&YEAR(B12) -> Q1-2025 | AC12: =D12&" → "&E12&" → "&F12 -> Asia → Japan → Osaka | AD12: =IF(OR(J12="Laptops",J12="Phones"),"Devices",IF(OR(J12="Monitors",J12="Printers"),"Peripherals","Support")) -> Devices | AE12: =IF(B12<=PERCENTILE($B$2:$B$632,0.33),"Low",IF(B12<=PERCENTILE($B$2:$B$632,0.66),"Medium","High")) -> High | AF12: =UPPER(TRIM(CLEAN(SUBSTITUTE(E12,CHAR(160),"")))) -> JAPAN | AG12: 44988 | AH12: =TEXT(AG12,"MMM-YYYY") -> Mar-2023 | AI12: =EOMONTH(B12,0) -> 45688 | AJ12: =IF(V12<=7,1,0) -> 0 | AK12: =IF(N12>20%,1,0) -> 1 | AL12: =MIN(N12,'Scenario Modelling'!$B$2) -> 0.25 | AM12: =L12*(1+'Scenario Modelling'!$B$3) -> 1044.89 | AN12: =O12*(1+'Scenario Modelling'!$B$4) -> 24 | AO12: =AN12*M12*(1-AL12) -> 12444.66 | AP12: =(M12*(1-AL12)-AM12)*AN12 -> -12632.7
A13: ORD-2025-487261 | B13: 45722 | C13: 45747 | D13: Americas | E13: Brazil | F13: Brasília | G13: Non-Profit | H13: Online | I13: J. Njeri | J13: Components | K13: CMP-3693 | L13: 331.57 | M13: 548.4 | N13: 0.094 | O13: 10 | P13: =IF(M13>0,"Valid") -> Valid | Q13: =ABS(M13) -> 548.4 | R13: =IF(N13>30%,"Excess") -> FALSE | S13: =IF(R13="Excess",30%,N13) -> 0.094 | T13: =(C13-B13) -> 25 | U13: =IF(C13<B13,B13+7,C13) -> 45747 | V13: =(U13-B13) -> 25 | W13: =(Q13*O13*(100-S13)) -> 547884.5 | X13: =(Q13*O13) -> 5484 | Y13: =W13-X13 -> 542400.5 | Z13: =Y13/W13 -> 0.98999059 | AA13: Mar-2025 | AB13: ="Q"&ROUNDUP(MONTH(B13)/3,0)&"-"&YEAR(B13) -> Q1-2025 | AC13: =D13&" → "&E13&" → "&F13 -> Americas → Brazil → Brasília | AD13: =IF(OR(J13="Laptops",J13="Phones"),"Devices",IF(OR(J13="Monitors",J13="Printers"),"Peripherals","Support")) -> Support | AE13: =IF(B13<=PERCENTILE($B$2:$B$632,0.33),"Low",IF(B13<=PERCENTILE($B$2:$B$632,0.66),"Medium","High")) -> High | AF13: =UPPER(TRIM(CLEAN(SUBSTITUTE(E13,CHAR(160),"")))) -> BRAZIL | AG13: =_xlfn.MINIFS($B$2:$B$633,$AF$2:$AF$633,AF13) -> 44955 | AH13: =TEXT(AG13,"MMM-YYYY") -> Jan-2023 | AI13: =EOMONTH(B13,0) -> 45747 | AJ13: =IF(V13<=7,1,0) -> 0 | AK13: =IF(N13>20%,1,0) -> 0 | AL13: =MIN(N13,'Scenario Modelling'!$B$2) -> 0.094 | AM13: =L13*(1+'Scenario Modelling'!$B$3) -> 381.3055 | AN13: =O13*(1+'Scenario Modelling'!$B$4) -> 12 | AO13: =AN13*M13*(1-AL13) -> 5962.2048 | AP13: =(M13*(1-AL13)-AM13)*AN13 -> 1386.5388
A14: ORD-2024-890180 | B14: 45311 | C14: 45335 | D14: Europe | E14: France | F14: Marseille | G14: Corporate | H14: Retail | I14: H. Kim | J14: Printers | K14: PRN-8392 | L14: 643.53 | M14: 1439.01 | N14: 0 | O14: 15 | P14: =IF(M14>0,"Valid") -> Valid | Q14: =ABS(M14) -> 1439.01 | R14: =IF(N14>30%,"Excess") -> FALSE | S14: =IF(R14="Excess",30%,N14) -> 0 | T14: =(C14-B14) -> 24 | U14: =IF(C14<B14,B14+7,C14) -> 45335 | V14: =(U14-B14) -> 24 | W14: =(Q14*O14*(100-S14)) -> 2158515 | X14: =(Q14*O14) -> 21585.15 | Y14: =W14-X14 -> 2136929.9 | Z14: =Y14/W14 -> 0.99 | AA14: Jan-2024 | AB14: ="Q"&ROUNDUP(MONTH(B14)/3,0)&"-"&YEAR(B14) -> Q1-2024 | AC14: =D14&" → "&E14&" → "&F14 -> Europe → France → Marseille | AD14: =IF(OR(J14="Laptops",J14="Phones"),"Devices",IF(OR(J14="Monitors",J14="Printers"),"Peripherals","Support")) -> Peripherals | AE14: =IF(B14<=PERCENTILE($B$2:$B$632,0.33),"Low",IF(B14<=PERCENTILE($B$2:$B$632,0.66),"Medium","High")) -> Medium | AF14: =UPPER(TRIM(CLEAN(SUBSTITUTE(E14,CHAR(160),"")))) -> FRANCE | AG14: =_xlfn.MINIFS($B$2:$B$633,$AF$2:$AF$633,AF14) -> 44936 | AH14: =TEXT(AG14,"MMM-YYYY") -> Jan-2023 | AI14: =EOMONTH(B14,0) -> 45322 | AJ14: =IF(V14<=7,1,0) -> 0 | AK14: =IF(N14>20%,1,0) -> 0 | AL14: =MIN(N14,'Scenario Modelling'!$B$2) -> 0 | AM14: =L14*(1+'Scenario Modelling'!$B$3) -> 740.0595 | AN14: =O14*(1+'Scenario Modelling'!$B$4) -> 18 | AO14: =AN14*M14*(1-AL14) -> 25902.18 | AP14: =(M14*(1-AL14)-AM14)*AN14 -> 12581.109
A15: ORD-2025-840976 | B15: 45901 | C15: 45930 | D15: Americas | E15: Brazil | F15: Brasília | G15: Education | H15: Retail | I15: K. Singh | J15: Accessories | K15: ACC-1663 | L15: 780.59 | M15: 631.57 | N15: 0 | O15: 12 | P15: =IF(M15>0,"Valid") -> Valid | Q15: =ABS(M15) -> 631.57 | R15: =IF(N15>30%,"Excess") -> FALSE | S15: =IF(R15="Excess",30%,N15) -> 0 | T15: =(C15-B15) -> 29 | U15: =IF(C15<B15,B15+7,C15) -> 45930 | V15: =(U15-B15) -> 29 | W15: =(Q15*O15*(100-S15)) -> 757884 | X15: =(Q15*O15) -> 7578.84 | Y15: =W15-X15 -> 750305.16 | Z15: =Y15/W15 -> 0.99 | AA15: Sep-2025 | AB15: ="Q"&ROUNDUP(MONTH(B15)/3,0)&"-"&YEAR(B15) -> Q3-2025 | AC15: =D15&" → "&E15&" → "&F15 -> Americas → Brazil → Brasília | AD15: =IF(OR(J15="Laptops",J15="Phones"),"Devices",IF(OR(J15="Monitors",J15="Printers"),"Peripherals","Support")) -> Support | AE15: =IF(B15<=PERCENTILE($B$2:$B$632,0.33),"Low",IF(B15<=PERCENTILE($B$2:$B$632,0.66),"Medium","High")) -> High | AF15: =UPPER(TRIM(CLEAN(SUBSTITUTE(E15,CHAR(160),"")))) -> BRAZIL | AG15: =_xlfn.MINIFS($B$2:$B$633,$AF$2:$AF$633,AF15) -> 44955 | AH15: =TEXT(AG15,"MMM-YYYY") -> Jan-2023 | AI15: =EOMONTH(B15,0) -> 45930 | AJ15: =IF(V15<=7,1,0) -> 0 | AK15: =IF(N15>20%,1,0) -> 0 | AL15: =MIN(N15,'Scenario Modelling'!$B$2) -> 0 | AM15: =L15*(1+'Scenario Modelling'!$B$3) -> 897.6785 | AN15: =O15*(1+'Scenario Modelling'!$B$4) -> 14.4 | AO15: =AN15*M15*(1-AL15) -> 9094.608 | AP15: =(M15*(1-AL15)-AM15)*AN15 -> -3831.9624
A16: ORD-2023-937291 | B16: 45039 | C16: 45038 | D16: Africa | E16: Kenya | F16: Nairobi | G16: Small Business | H16: Direct | I16: E. Garcia | J16: Laptops | K16: LAP-1698 | L16: 756.51 | M16: 850.8 | N16: 0.074 | O16: 9 | P16: =IF(M16>0,"Valid") -> Valid | Q16: =ABS(M16) -> 850.8 | R16: =IF(N16>30%,"Excess") -> FALSE | S16: =IF(R16="Excess",30%,N16) -> 0.074 | T16: =(C16-B16) -> -1 | U16: =IF(C16<B16,B16+7,C16) -> 45046 | V16: =(U16-B16) -> 7 | W16: =(Q16*O16*(100-S16)) -> 765153.37 | X16: =(Q16*O16) -> 7657.2 | Y16: =W16-X16 -> 757496.17 | Z16: =Y16/W16 -> 0.98999259 | AA16: Apr-2023 | AB16: ="Q"&ROUNDUP(MONTH(B16)/3,0)&"-"&YEAR(B16) -> Q2-2023 | AC16: =D16&" → "&E16&" → "&F16 -> Africa → Kenya → Nairobi | AD16: =IF(OR(J16="Laptops",J16="Phones"),"Devices",IF(OR(J16="Monitors",J16="Printers"),"Peripherals","Support")) -> Devices | AE16: =IF(B16<=PERCENTILE($B$2:$B$632,0.33),"Low",IF(B16<=PERCENTILE($B$2:$B$632,0.66),"Medium","High")) -> Low | AF16: =UPPER(TRIM(CLEAN(SUBSTITUTE(E16,CHAR(160),"")))) -> KENYA | AG16: 44946 | AH16: =TEXT(AG16,"MMM-YYYY") -> Jan-2023 | AI16: =EOMONTH(B16,0) -> 45046 | AJ16: =IF(V16<=7,1,0) -> 1 | AK16: =IF(N16>20%,1,0) -> 0 | AL16: =MIN(N16,'Scenario Modelling'!$B$2) -> 0.074 | AM16: =L16*(1+'Scenario Modelling'!$B$3) -> 869.9865 | AN16: =O16*(1+'Scenario Modelling'!$B$4) -> 10.8 | AO16: =AN16*M16*(1-AL16) -> 8508.6806 | AP16: =(M16*(1-AL16)-AM16)*AN16 -> -887.17356
A17: ORD-2024-206081 | B17: 45636 | C17: 45665 | D17: Europe | E17: France | F17: Marseille | G17: Small Business | H17: Retail | I17: K. Singh | J17: Printers | K17: PRN-6791 | L17: 891.08 | M17: 1040.1 | N17: 0.109 | O17: 28 | P17: =IF(M17>0,"Valid") -> Valid | Q17: =ABS(M17) -> 1040.1 | R17: =IF(N17>30%,"Excess") -> FALSE | S17: =IF(R17="Excess",30%,N17) -> 0.109 | T17: =(C17-B17) -> 29 | U17: =IF(C17<B17,B17+7,C17) -> 45665 | V17: =(U17-B17) -> 29 | W17: =(Q17*O17*(100-S17)) -> 2909105.6 | X17: =(Q17*O17) -> 29122.8 | Y17: =W17-X17 -> 2879982.8 | Z17: =Y17/W17 -> 0.98998909 | AA17: Dec-2024 | AB17: ="Q"&ROUNDUP(MONTH(B17)/3,0)&"-"&YEAR(B17) -> Q4-2024 | AC17: =D17&" → "&E17&" → "&F17 -> Europe → France → Marseille | AD17: =IF(OR(J17="Laptops",J17="Phones"),"Devices",IF(OR(J17="Monitors",J17="Printers"),"Peripherals","Support")) -> Peripherals | AE17: =IF(B17<=PERCENTILE($B$2:$B$632,0.33),"Low",IF(B17<=PERCENTILE($B$2:$B$632,0.66),"Medium","High")) -> High | AF17: =UPPER(TRIM(CLEAN(SUBSTITUTE(E17,CHAR(160),"")))) -> FRANCE | AG17: 44936 | AH17: =TEXT(AG17,"MMM-YYYY") -> Jan-2023 | AI17: =EOMONTH(B17,0) -> 45657 | AJ17: =IF(V17<=7,1,0) -> 0 | AK17: =IF(N17>20%,1,0) -> 0 | AL17: =MIN(N17,'Scenario Modelling'!$B$2) -> 0.109 | AM17: =L17*(1+'Scenario Modelling'!$B$3) -> 1024.742 | AN17: =O17*(1+'Scenario Modelling'!$B$4) -> 33.6 | AO17: =AN17*M17*(1-AL17) -> 31138.098 | AP17: =(M17*(1-AL17)-AM17)*AN17 -> -3293.2334
A18: ORD-2025-233883 | B18: 45908 | C18: 45916 | D18: Asia | E18: Japan | F18: Osaka | G18: Corporate | H18: Distributor | I18: C. Otieno | J18: Phones | K18: PHN-1197 | L18: 1225.57 | M18: 2705.57 | N18: 0.183 | O18: 16 | P18: =IF(M18>0,"Valid") -> Valid | Q18: =ABS(M18) -> 2705.57 | R18: =IF(N18>30%,"Excess") -> FALSE | S18: =IF(R18="Excess",30%,N18) -> 0.183 | T18: =(C18-B18) -> 8 | U18: =IF(C18<B18,B18+7,C18) -> 45916 | V18: =(U18-B18) -> 8 | W18: =(Q18*O18*(100-S18)) -> 4320990.1 | X18: =(Q18*O18) -> 43289.12 | Y18: =W18-X18 -> 4277701 | Z18: =Y18/W18 -> 0.98998167 | AA18: Sep-2025 | AB18: ="Q"&ROUNDUP(MONTH(B18)/3,0)&"-"&YEAR(B18) -> Q3-2025 | AC18: =D18&" → "&E18&" → "&F18 -> Asia → Japan → Osaka | AD18: =IF(OR(J18="Laptops",J18="Phones"),"Devices",IF(OR(J18="Monitors",J18="Printers"),"Peripherals","Support")) -> Devices | AE18: =IF(B18<=PERCENTILE($B$2:$B$632,0.33),"Low",IF(B18<=PERCENTILE($B$2:$B$632,0.66),"Medium","High")) -> High | AF18: =UPPER(TRIM(CLEAN(SUBSTITUTE(E18,CHAR(160),"")))) -> JAPAN | AG18: 44988 | AH18: =TEXT(AG18,"MMM-YYYY") -> Mar-2023 | AI18: =EOMONTH(B18,0) -> 45930 | AJ18: =IF(V18<=7,1,0) -> 0 | AK18: =IF(N18>20%,1,0) -> 0 | AL18: =MIN(N18,'Scenario Modelling'!$B$2) -> 0.183 | AM18: =L18*(1+'Scenario Modelling'!$B$3) -> 1409.4055 | AN18: =O18*(1+'Scenario Modelling'!$B$4) -> 19.2 | AO18: =AN18*M18*(1-AL18) -> 42440.653 | AP18: =(M18*(1-AL18)-AM18)*AN18 -> 15380.068
A19: ORD-2025-843974 | B19: 45858 | C19: 45874 | D19: Americas | E19: Brazil | F19: Brasília | G19: Enterprise | H19: Marketplace | I19: G. Dubois | J19: Accessories | K19: ACC-8098 | L19: 1068.17 | M19: 2375.37 | N19: 0.109 | O19: 18 | P19: =IF(M19>0,"Valid") -> Valid | Q19: =ABS(M19) -> 2375.37 | R19: =IF(N19>30%,"Excess") -> FALSE | S19: =IF(R19="Excess",30%,N19) -> 0.109 | T19: =(C19-B19) -> 16 | U19: =IF(C19<B19,B19+7,C19) -> 45874 | V19: =(U19-B19) -> 16 | W19: =(Q19*O19*(100-S19)) -> 4271005.5 | X19: =(Q19*O19) -> 42756.66 | Y19: =W19-X19 -> 4228248.9 | Z19: =Y19/W19 -> 0.98998909 | AA19: Jul-2025 | AB19: ="Q"&ROUNDUP(MONTH(B19)/3,0)&"-"&YEAR(B19) -> Q3-2025 | AC19: =D19&" → "&E19&" → "&F19 -> Americas → Brazil → Brasília | AD19: =IF(OR(J19="Laptops",J19="Phones"),"Devices",IF(OR(J19="Monitors",J19="Printers"),"Peripherals","Support")) -> Support | AE19: =IF(B19<=PERCENTILE($B$2:$B$632,0.33),"Low",IF(B19<=PERCENTILE($B$2:$B$632,0.66),"Medium","High")) -> High | AF19: =UPPER(TRIM(CLEAN(SUBSTITUTE(E19,CHAR(160),"")))) -> BRAZIL | AG19: =_xlfn.MINIFS($B$2:$B$633,$AF$2:$AF$633,AF19) -> 44955 | AH19: =TEXT(AG19,"MMM-YYYY") -> Jan-2023 | AI19: =EOMONTH(B19,0) -> 45869 | AJ19: =IF(V19<=7,1,0) -> 0 | AK19: =IF(N19>20%,1,0) -> 0 | AL19: =MIN(N19,'Scenario Modelling'!$B$2) -> 0.109 | AM19: =L19*(1+'Scenario Modelling'!$B$3) -> 1228.3955 | AN19: =O19*(1+'Scenario Modelling'!$B$4) -> 21.6 | AO19: =AN19*M19*(1-AL19) -> 45715.421 | AP19: =(M19*(1-AL19)-AM19)*AN19 -> 19182.078
A20: ORD-2025-745263 | B20: 45798 | C20: 45796 | D20: Europe | E20: United Kingdom | F20: Birmingham | G20: Enterprise | H20: Online | I20: M. Rossi | J20: Laptops | K20: LAP-3385 | L20: 1015.16 | M20: 2148.14 | N20: 0.038 | O20: 19 | P20: =IF(M20>0,"Valid") -> Valid | Q20: =ABS(M20) -> 2148.14 | R20: =IF(N20>30%,"Excess") -> FALSE | S20: =IF(R20="Excess",30%,N20) -> 0.038 | T20: =(C20-B20) -> -2 | U20: =IF(C20<B20,B20+7,C20) -> 45805 | V20: =(U20-B20) -> 7 | W20: =(Q20*O20*(100-S20)) -> 4079915 | X20: =(Q20*O20) -> 40814.66 | Y20: =W20-X20 -> 4039100.4 | Z20: =Y20/W20 -> 0.9899962 | AA20: May-2025 | AB20: ="Q"&ROUNDUP(MONTH(B20)/3,0)&"-"&YEAR(B20) -> Q2-2025 | AC20: =D20&" → "&E20&" → "&F20 -> Europe → United Kingdom → Birmingham | AD20: =IF(OR(J20="Laptops",J20="Phones"),"Devices",IF(OR(J20="Monitors",J20="Printers"),"Peripherals","Support")) -> Devices | AE20: =IF(B20<=PERCENTILE($B$2:$B$632,0.33),"Low",IF(B20<=PERCENTILE($B$2:$B$632,0.66),"Medium","High")) -> High | AF20: =UPPER(TRIM(CLEAN(SUBSTITUTE(E20,CHAR(160),"")))) -> UNITED KINGDOM | AG20: 44945 | AH20: =TEXT(AG20,"MMM-YYYY") -> Jan-2023 | AI20: =EOMONTH(B20,0) -> 45808 | AJ20: =IF(V20<=7,1,0) -> 1 | AK20: =IF(N20>20%,1,0) -> 0 | AL20: =MIN(N20,'Scenario Modelling'!$B$2) -> 0.038 | AM20: =L20*(1+'Scenario Modelling'!$B$3) -> 1167.434 | AN20: =O20*(1+'Scenario Modelling'!$B$4) -> 22.8 | AO20: =AN20*M20*(1-AL20) -> 47116.444 | AP20: =(M20*(1-AL20)-AM20)*AN20 -> 20498.948
A21: ORD-2024-798002 | B21: 45498 | C21: 45497 | D21: Africa | E21: Kenya | F21: Mombasa | G21: Non-Profit | H21: Direct | I21: J. Njeri | J21: Laptops | K21: LAP-9815 | L21: 1494.4 | M21: 3661.07 | N21: 0.072 | O21: 7 | P21: =IF(M21>0,"Valid") -> Valid | Q21: =ABS(M21) -> 3661.07 | R21: =IF(N21>30%,"Excess") -> FALSE | S21: =IF(R21="Excess",30%,N21) -> 0.072 | T21: =(C21-B21) -> -1 | U21: =IF(C21<B21,B21+7,C21) -> 45505 | V21: =(U21-B21) -> 7 | W21: =(Q21*O21*(100-S21)) -> 2560903.8 | X21: =(Q21*O21) -> 25627.49 | Y21: =W21-X21 -> 2535276.3 | Z21: =Y21/W21 -> 0.98999279 | AA21: Jul-2024 | AB21: ="Q"&ROUNDUP(MONTH(B21)/3,0)&"-"&YEAR(B21) -> Q3-2024 | AC21: =D21&" → "&E21&" → "&F21 -> Africa → Kenya → Mombasa | AD21: =IF(OR(J21="Laptops",J21="Phones"),"Devices",IF(OR(J21="Monitors",J21="Printers"),"Peripherals","Support")) -> Devices | AE21: =IF(B21<=PERCENTILE($B$2:$B$632,0.33),"Low",IF(B21<=PERCENTILE($B$2:$B$632,0.66),"Medium","High")) -> Medium | AF21: =UPPER(TRIM(CLEAN(SUBSTITUTE(E21,CHAR(160),"")))) -> KENYA | AG21: 44946 | AH21: =TEXT(AG21,"MMM-YYYY") -> Jan-2023 | AI21: =EOMONTH(B21,0) -> 45504 | AJ21: =IF(V21<=7,1,0) -> 1 | AK21: =IF(N21>20%,1,0) -> 0 | AL21: =MIN(N21,'Scenario Modelling'!$B$2) -> 0.072 | AM21: =L21*(1+'Scenario Modelling'!$B$3) -> 1718.56 | AN21: =O21*(1+'Scenario Modelling'!$B$4) -> 8.4 | AO21: =AN21*M21*(1-AL21) -> 28538.773 | AP21: =(M21*(1-AL21)-AM21)*AN21 -> 14102.869
A22: ORD-2023-867836 | B22: 45057 | C22: 45074 | D22: Asia | E22: China | F22: Shenzhen | G22: Enterprise | H22: Marketplace | I22: E. Garcia | J22: Networking | K22: NET-3255 | L22: 1331.19 | M22: 2903.09 | N22: 0.143 | O22: 8 | P22: =IF(M22>0,"Valid") -> Valid | Q22: =ABS(M22) -> 2903.09 | R22: =IF(N22>30%,"Excess") -> FALSE | S22: =IF(R22="Excess",30%,N22) -> 0.143 | T22: =(C22-B22) -> 17 | U22: =IF(C22<B22,B22+7,C22) -> 45074 | V22: =(U22-B22) -> 17 | W22: =(Q22*O22*(100-S22)) -> 2319150.9 | X22: =(Q22*O22) -> 23224.72 | Y22: =W22-X22 -> 2295926.1 | Z22: =Y22/W22 -> 0.98998568 | AA22: May-2023 | AB22: ="Q"&ROUNDUP(MONTH(B22)/3,0)&"-"&YEAR(B22) -> Q2-2023 | AC22: =D22&" → "&E22&" → "&F22 -> Asia → China → Shenzhen | AD22: =IF(OR(J22="Laptops",J22="Phones"),"Devices",IF(OR(J22="Monitors",J22="Printers"),"Peripherals","Support")) -> Support | AE22: =IF(B22<=PERCENTILE($B$2:$B$632,0.33),"Low",IF(B22<=PERCENTILE($B$2:$B$632,0.66),"Medium","High")) -> Low | AF22: =UPPER(TRIM(CLEAN(SUBSTITUTE(E22,CHAR(160),"")))) -> CHINA | AG22: =_xlfn.MINIFS($B$2:$B$633,$AF$2:$AF$633,AF22) -> 44938 | AH22: =TEXT(AG22,"MMM-YYYY") -> Jan-2023 | AI22: =EOMONTH(B22,0) -> 45077 | AJ22: =IF(V22<=7,1,0) -> 0 | AK22: =IF(N22>20%,1,0) -> 0 | AL22: =MIN(N22,'Scenario Modelling'!$B$2) -> 0.143 | AM22: =L22*(1+'Scenario Modelling'!$B$3) -> 1530.8685 | AN22: =O22*(1+'Scenario Modelling'!$B$4) -> 9.6 | AO22: =AN22*M22*(1-AL22) -> 23884.302 | AP22: =(M22*(1-AL22)-AM22)*AN22 -> 9187.9644
A23: ORD-2025-580047 | B23: 45822 | C23: 45837 | D23: Africa | E23: Nigeria | F23: Port Harcourt | G23: Consumer | H23: Marketplace | I23: M. Rossi | J23: Accessories | K23: ACC-3961 | L23: 730.99 | M23: 1242.84 | N23: 0.12 | O23: 10 | P23: =IF(M23>0,"Valid") -> Valid | Q23: =ABS(M23) -> 1242.84 | R23: =IF(N23>30%,"Excess") -> FALSE | S23: =IF(R23="Excess",30%,N23) -> 0.12 | T23: =(C23-B23) -> 15 | U23: =IF(C23<B23,B23+7,C23) -> 45837 | V23: =(U23-B23) -> 15 | W23: =(Q23*O23*(100-S23)) -> 1241348.6 | X23: =(Q23*O23) -> 12428.4 | Y23: =W23-X23 -> 1228920.2 | Z23: =Y23/W23 -> 0.98998799 | AA23: Jun-2025 | AB23: ="Q"&ROUNDUP(MONTH(B23)/3,0)&"-"&YEAR(B23) -> Q2-2025 | AC23: =D23&" → "&E23&" → "&F23 -> Africa → Nigeria → Port Harcourt | AD23: =IF(OR(J23="Laptops",J23="Phones"),"Devices",IF(OR(J23="Monitors",J23="Printers"),"Peripherals","Support")) -> Support | AE23: =IF(B23<=PERCENTILE($B$2:$B$632,0.33),"Low",IF(B23<=PERCENTILE($B$2:$B$632,0.66),"Medium","High")) -> High | AF23: =UPPER(TRIM(CLEAN(SUBSTITUTE(E23,CHAR(160),"")))) -> NIGERIA | AG23: =_xlfn.MINIFS($B$2:$B$633,$AF$2:$AF$633,AF23) -> 44941 | AH23: =TEXT(AG23,"MMM-YYYY") -> Jan-2023 | AI23: =EOMONTH(B23,0) -> 45838 | AJ23: =IF(V23<=7,1,0) -> 0 | AK23: =IF(N23>20%,1,0) -> 0 | AL23: =MIN(N23,'Scenario Modelling'!$B$2) -> 0.12 | AM23: =L23*(1+'Scenario Modelling'!$B$3) -> 840.6385 | AN23: =O23*(1+'Scenario Modelling'!$B$4) -> 12 | AO23: =AN23*M23*(1-AL23) -> 13124.39 | AP23: =(M23*(1-AL23)-AM23)*AN23 -> 3036.7284
A24: ORD-2024-500109 | B24: 45430 | C24: 45435 | D24: Americas | E24: USA | F24: Chicago | G24: Enterprise | H24: Retail | I24: H. Kim | J24: Laptops | K24: LAP-4987 | L24: 1274.59 | M24: 2553.69 | N24: 0.01 | O24: 8 | P24: =IF(M24>0,"Valid") -> Valid | Q24: =ABS(M24) -> 2553.69 | R24: =IF(N24>30%,"Excess") -> FALSE | S24: =IF(R24="Excess",30%,N24) -> 0.01 | T24: =(C24-B24) -> 5 | U24: =IF(C24<B24,B24+7,C24) -> 45435 | V24: =(U24-B24) -> 5 | W24: =(Q24*O24*(100-S24)) -> 2042747.7 | X24: =(Q24*O24) -> 20429.52 | Y24: =W24-X24 -> 2022318.2 | Z24: =Y24/W24 -> 0.989999 | AA24: May-2024 | AB24: ="Q"&ROUNDUP(MONTH(B24)/3,0)&"-"&YEAR(B24) -> Q2-2024 | AC24: =D24&" → "&E24&" → "&F24 -> Americas → USA → Chicago | AD24: =IF(OR(J24="Laptops",J24="Phones"),"Devices",IF(OR(J24="Monitors",J24="Printers"),"Peripherals","Support")) -> Devices | AE24: =IF(B24<=PERCENTILE($B$2:$B$632,0.33),"Low",IF(B24<=PERCENTILE($B$2:$B$632,0.66),"Medium","High")) -> Medium | AF24: =UPPER(TRIM(CLEAN(SUBSTITUTE(E24,CHAR(160),"")))) -> USA | AG24: 44939 | AH24: =TEXT(AG24,"MMM-YYYY") -> Jan-2023 | AI24: =EOMONTH(B24,0) -> 45443 | AJ24: =IF(V24<=7,1,0) -> 1 | AK24: =IF(N24>20%,1,0) -> 0 | AL24: =MIN(N24,'Scenario Modelling'!$B$2) -> 0.01 | AM24: =L24*(1+'Scenario Modelling'!$B$3) -> 1465.7785 | AN24: =O24*(1+'Scenario Modelling'!$B$4) -> 9.6 | AO24: =AN24*M24*(1-AL24) -> 24270.27 | AP24: =(M24*(1-AL24)-AM24)*AN24 -> 10198.796
A25: ORD-2023-271836 | B25: 44964 | C25: 44969 | D25: Americas | E25: Brazil | F25: São Paulo | G25: Education | H25: Online | I25: N. Brown | J25: Components | K25: CMP-2693 | L25: 948.55 | M25: 2089.16 | N25: 0.007 | O25: 12 | P25: =IF(M25>0,"Valid") -> Valid | Q25: =ABS(M25) -> 2089.16 | R25: =IF(N25>30%,"Excess") -> FALSE | S25: =IF(R25="Excess",30%,N25) -> 0.007 | T25: =(C25-B25) -> 5 | U25: =IF(C25<B25,B25+7,C25) -> 44969 | V25: =(U25-B25) -> 5 | W25: =(Q25*O25*(100-S25)) -> 2506816.5 | X25: =(Q25*O25) -> 25069.92 | Y25: =W25-X25 -> 2481746.6 | Z25: =Y25/W25 -> 0.9899993 | AA25: Feb-2023 | AB25: ="Q"&ROUNDUP(MONTH(B25)/3,0)&"-"&YEAR(B25) -> Q1-2023 | AC25: =D25&" → "&E25&" → "&F25 -> Americas → Brazil → São Paulo | AD25: =IF(OR(J25="Laptops",J25="Phones"),"Devices",IF(OR(J25="Monitors",J25="Printers"),"Peripherals","Support")) -> Support | AE25: =IF(B25<=PERCENTILE($B$2:$B$632,0.33),"Low",IF(B25<=PERCENTILE($B$2:$B$632,0.66),"Medium","High")) -> Low | AF25: =UPPER(TRIM(CLEAN(SUBSTITUTE(E25,CHAR(160),"")))) -> BRAZIL | AG25: =_xlfn.MINIFS($B$2:$B$633,$AF$2:$AF$633,AF25) -> 44955 | AH25: =TEXT(AG25,"MMM-YYYY") -> Jan-2023 | AI25: =EOMONTH(B25,0) -> 44985 | AJ25: =IF(V25<=7,1,0) -> 1 | AK25: =IF(N25>20%,1,0) -> 0 | AL25: =MIN(N25,'Scenario Modelling'!$B$2) -> 0.007 | AM25: =L25*(1+'Scenario Modelling'!$B$3) -> 1090.8325 | AN25: =O25*(1+'Scenario Modelling'!$B$4) -> 14.4 | AO25: =AN25*M25*(1-AL25) -> 29873.317 | AP25: =(M25*(1-AL25)-AM25)*AN25 -> 14165.329
A26: ORD-2024-215294 | B26: 45473 | C26: 45487 | D26: Americas | E26: Brazil | F26: Brasília | G26: Education | H26: Retail | I26: C. Otieno | J26: Accessories | K26: ACC-8683 | L26: 1491.85 | M26: 2583.02 | N26: 0.168 | O26: 4 | P26: =IF(M26>0,"Valid") -> Valid | Q26: =ABS(M26) -> 2583.02 | R26: =IF(N26>30%,"Excess") -> FALSE | S26: =IF(R26="Excess",30%,N26) -> 0.168 | T26: =(C26-B26) -> 14 | U26: =IF(C26<B26,B26+7,C26) -> 45487 | V26: =(U26-B26) -> 14 | W26: =(Q26*O26*(100-S26)) -> 1031472.2 | X26: =(Q26*O26) -> 10332.08 | Y26: =W26-X26 -> 1021140.1 | Z26: =Y26/W26 -> 0.98998317 | AA26: Jun-2024 | AB26: ="Q"&ROUNDUP(MONTH(B26)/3,0)&"-"&YEAR(B26) -> Q2-2024 | AC26: =D26&" → "&E26&" → "&F26 -> Americas → Brazil → Brasília | AD26: =IF(OR(J26="Laptops",J26="Phones"),"Devices",IF(OR(J26="Monitors",J26="Printers"),"Peripherals","Support")) -> Support | AE26: =IF(B26<=PERCENTILE($B$2:$B$632,0.33),"Low",IF(B26<=PERCENTILE($B$2:$B$632,0.66),"Medium","High")) -> Medium | AF26: =UPPER(TRIM(CLEAN(SUBSTITUTE(E26,CHAR(160),"")))) -> BRAZIL | AG26: =_xlfn.MINIFS($B$2:$B$633,$AF$2:$AF$633,AF26) -> 44955 | AH26: =TEXT(AG26,"MMM-YYYY") -> Jan-2023 | AI26: =EOMONTH(B26,0) -> 45473 | AJ26: =IF(V26<=7,1,0) -> 0 | AK26: =IF(N26>20%,1,0) -> 0 | AL26: =MIN(N26,'Scenario Modelling'!$B$2) -> 0.168 | AM26: =L26*(1+'Scenario Modelling'!$B$3) -> 1715.6275 | AN26: =O26*(1+'Scenario Modelling'!$B$4) -> 4.8 | AO26: =AN26*M26*(1-AL26) -> 10315.549 | AP26: =(M26*(1-AL26)-AM26)*AN26 -> 2080.5367
A27: ORD-2024-788105 | B27: 45626 | C27: 45656 | D27: Europe | E27: France | F27: Marseille | G27: Consumer | H27: Marketplace | I27: F. Müller | J27: Printers | K27: PRN-4170 | L27: 117.64 | M27: 175.67 | N27: 0 | O27: 10 | P27: =IF(M27>0,"Valid") -> Valid | Q27: =ABS(M27) -> 175.67 | R27: =IF(N27>30%,"Excess") -> FALSE | S27: =IF(R27="Excess",30%,N27) -> 0 | T27: =(C27-B27) -> 30 | U27: =IF(C27<B27,B27+7,C27) -> 45656 | V27: =(U27-B27) -> 30 | W27: =(Q27*O27*(100-S27)) -> 175670 | X27: =(Q27*O27) -> 1756.7 | Y27: =W27-X27 -> 173913.3 | Z27: =Y27/W27 -> 0.99 | AA27: Nov-2024 | AB27: ="Q"&ROUNDUP(MONTH(B27)/3,0)&"-"&YEAR(B27) -> Q4-2024 | AC27: =D27&" → "&E27&" → "&F27 -> Europe → France → Marseille | AD27: =IF(OR(J27="Laptops",J27="Phones"),"Devices",IF(OR(J27="Monitors",J27="Printers"),"Peripherals","Support")) -> Peripherals | AE27: =IF(B27<=PERCENTILE($B$2:$B$632,0.33),"Low",IF(B27<=PERCENTILE($B$2:$B$632,0.66),"Medium","High")) -> High | AF27: =UPPER(TRIM(CLEAN(SUBSTITUTE(E27,CHAR(160),"")))) -> FRANCE | AG27: 44936 | AH27: =TEXT(AG27,"MMM-YYYY") -> Jan-2023 | AI27: =EOMONTH(B27,0) -> 45626 | AJ27: =IF(V27<=7,1,0) -> 0 | AK27: =IF(N27>20%,1,0) -> 0 | AL27: =MIN(N27,'Scenario Modelling'!$B$2) -> 0 | AM27: =L27*(1+'Scenario Modelling'!$B$3) -> 135.286 | AN27: =O27*(1+'Scenario Modelling'!$B$4) -> 12 | AO27: =AN27*M27*(1-AL27) -> 2108.04 | AP27: =(M27*(1-AL27)-AM27)*AN27 -> 484.608
A28: ORD-2024-855073 | B28: 45492 | C28: 45492 | D28: Africa | E28: Kenya | F28: Kisumu | G28: Small Business | H28: Retail | I28: A. Patel | J28: Phones | K28: PHN-6854 | L28: 857.24 | M28: 758.23 | N28: 0.125 | O28: 6 | P28: =IF(M28>0,"Valid") -> Valid | Q28: =ABS(M28) -> 758.23 | R28: =IF(N28>30%,"Excess") -> FALSE | S28: =IF(R28="Excess",30%,N28) -> 0.125 | T28: =(C28-B28) -> 0 | U28: =IF(C28<B28,B28+7,C28) -> 45492 | V28: =(U28-B28) -> 0 | W28: =(Q28*O28*(100-S28)) -> 454369.33 | X28: =(Q28*O28) -> 4549.38 | Y28: =W28-X28 -> 449819.95 | Z28: =Y28/W28 -> 0.98998748 | AA28: Jul-2024 | AB28: ="Q"&ROUNDUP(MONTH(B28)/3,0)&"-"&YEAR(B28) -> Q3-2024 | AC28: =D28&" → "&E28&" → "&F28 -> Africa → Kenya → Kisumu | AD28: =IF(OR(J28="Laptops",J28="Phones"),"Devices",IF(OR(J28="Monitors",J28="Printers"),"Peripherals","Support")) -> Devices | AE28: =IF(B28<=PERCENTILE($B$2:$B$632,0.33),"Low",IF(B28<=PERCENTILE($B$2:$B$632,0.66),"Medium","High")) -> Medium | AF28: =UPPER(TRIM(CLEAN(SUBSTITUTE(E28,CHAR(160),"")))) -> KENYA | AG28: 44946 | AH28: =TEXT(AG28,"MMM-YYYY") -> Jan-2023 | AI28: =EOMONTH(B28,0) -> 45504 | AJ28: =IF(V28<=7,1,0) -> 1 | AK28: =IF(N28>20%,1,0) -> 0 | AL28: =MIN(N28,'Scenario Modelling'!$B$2) -> 0.125 | AM28: =L28*(1+'Scenario Modelling'!$B$3) -> 985.826 | AN28: =O28*(1+'Scenario Modelling'!$B$4) -> 7.2 | AO28: =AN28*M28*(1-AL28) -> 4776.849 | AP28: =(M28*(1-AL28)-AM28)*AN28 -> -2321.0982
A29: ORD-2023-897079 | B29: 45030 | C29: 45060 | D29: Africa | E29: Kenya | F29: Nakuru | G29: Consumer | H29: Marketplace | I29: M. Rossi | J29: Phones | K29: PHN-1784 | L29: 209.25 | M29: 434.8 | N29: 0 | O29: 9 | P29: =IF(M29>0,"Valid") -> Valid | Q29: =ABS(M29) -> 434.8 | R29: =IF(N29>30%,"Excess") -> FALSE | S29: =IF(R29="Excess",30%,N29) -> 0 | T29: =(C29-B29) -> 30 | U29: =IF(C29<B29,B29+7,C29) -> 45060 | V29: =(U29-B29) -> 30 | W29: =(Q29*O29*(100-S29)) -> 391320 | X29: =(Q29*O29) -> 3913.2 | Y29: =W29-X29 -> 387406.8 | Z29: =Y29/W29 -> 0.99 | AA29: Apr-2023 | AB29: ="Q"&ROUNDUP(MONTH(B29)/3,0)&"-"&YEAR(B29) -> Q2-2023 | AC29: =D29&" → "&E29&" → "&F29 -> Africa → Kenya → Nakuru | AD29: =IF(OR(J29="Laptops",J29="Phones"),"Devices",IF(OR(J29="Monitors",J29="Printers"),"Peripherals","Support")) -> Devices | AE29: =IF(B29<=PERCENTILE($B$2:$B$632,0.33),"Low",IF(B29<=PERCENTILE($B$2:$B$632,0.66),"Medium","High")) -> Low | AF29: =UPPER(TRIM(CLEAN(SUBSTITUTE(E29,CHAR(160),"")))) -> KENYA | AG29: 44946 | AH29: =TEXT(AG29,"MMM-YYYY") -> Jan-2023 | AI29: =EOMONTH(B29,0) -> 45046 | AJ29: =IF(V29<=7,1,0) -> 0 | AK29: =IF(N29>20%,1,0) -> 0 | AL29: =MIN(N29,'Scenario Modelling'!$B$2) -> 0 | AM29: =L29*(1+'Scenario Modelling'!$B$3) -> 240.6375 | AN29: =O29*(1+'Scenario Modelling'!$B$4) -> 10.8 | AO29: =AN29*M29*(1-AL29) -> 4695.84 | AP29: =(M29*(1-AL29)-AM29)*AN29 -> 2096.955
A30: ORD-2025-548982 | B30: 45754 | C30: 45758 | D30: Europe | E30: France | F30: Lyon | G30: Education | H30: Retail | I30: E. Garcia | J30: Networking | K30: NET-9716 | L30: 754.77 | M30: 1666.18 | N30: 0.139 | O30: 14 | P30: =IF(M30>0,"Valid") -> Valid | Q30: =ABS(M30) -> 1666.18 | R30: =IF(N30>30%,"Excess") -> FALSE | S30: =IF(R30="Excess",30%,N30) -> 0.139 | T30: =(C30-B30) -> 4 | U30: =IF(C30<B30,B30+7,C30) -> 45758 | V30: =(U30-B30) -> 4 | W30: =(Q30*O30*(100-S30)) -> 2329409.6 | X30: =(Q30*O30) -> 23326.52 | Y30: =W30-X30 -> 2306083.1 | Z30: =Y30/W30 -> 0.98998608 | AA30: Apr-2025 | AB30: ="Q"&ROUNDUP(MONTH(B30)/3,0)&"-"&YEAR(B30) -> Q2-2025 | AC30: =D30&" → "&E30&" → "&F30 -> Europe → France → Lyon | AD30: =IF(OR(J30="Laptops",J30="Phones"),"Devices",IF(OR(J30="Monitors",J30="Printers"),"Peripherals","Support")) -> Support | AE30: =IF(B30<=PERCENTILE($B$2:$B$632,0.33),"Low",IF(B30<=PERCENTILE($B$2:$B$632,0.66),"Medium","High")) -> High | AF30: =UPPER(TRIM(CLEAN(SUBSTITUTE(E30,CHAR(160),"")))) -> FRANCE | AG30: 44936 | AH30: =TEXT(AG30,"MMM-YYYY") -> Jan-2023 | AI30: =EOMONTH(B30,0) -> 45777 | AJ30: =IF(V30<=7,1,0) -> 1 | AK30: =IF(N30>20%,1,0) -> 0 | AL30: =MIN(N30,'Scenario Modelling'!$B$2) -> 0.139 | AM30: =L30*(1+'Scenario Modelling'!$B$3) -> 867.9855 | AN30: =O30*(1+'Scenario Modelling'!$B$4) -> 16.8 | AO30: =AN30*M30*(1-AL30) -> 24100.96 | AP30: =(M30*(1-AL30)-AM30)*AN30 -> 9518.8041
A31: ORD-2024-170313 | B31: 45653 | C31: 45672 | D31: Asia | E31: India | F31: Delhi | G31: Non-Profit | H31: Distributor | I31: G. Dubois | J31: Components | K31: CMP-6919 | L31: 495.59 | M31: 631.78 | N31: 0.087 | O31: 17 | P31: =IF(M31>0,"Valid") -> Valid | Q31: =ABS(M31) -> 631.78 | R31: =IF(N31>30%,"Excess") -> FALSE | S31: =IF(R31="Excess",30%,N31) -> 0.087 | T31: =(C31-B31) -> 19 | U31: =IF(C31<B31,B31+7,C31) -> 45672 | V31: =(U31-B31) -> 19 | W31: =(Q31*O31*(100-S31)) -> 1073091.6 | X31: =(Q31*O31) -> 10740.26 | Y31: =W31-X31 -> 1062351.3 | Z31: =Y31/W31 -> 0.98999129 | AA31: Dec-2024 | AB31: ="Q"&ROUNDUP(MONTH(B31)/3,0)&"-"&YEAR(B31) -> Q4-2024 | AC31: =D31&" → "&E31&" → "&F31 -> Asia → India → Delhi | AD31: =IF(OR(J31="Laptops",J31="Phones"),"Devices",IF(OR(J31="Monitors",J31="Printers"),"Peripherals","Support")) -> Support | AE31: =IF(B31<=PERCENTILE($B$2:$B$632,0.33),"Low",IF(B31<=PERCENTILE($B$2:$B$632,0.66),"Medium","High")) -> High | AF31: =UPPER(TRIM(CLEAN(SUBSTITUTE(E31,CHAR(160),"")))) -> INDIA | AG31: 44955 | AH31: =TEXT(AG31,"MMM-YYYY") -> Jan-2023 | AI31: =EOMONTH(B31,0) -> 45657 | AJ31: =IF(V31<=7,1,0) -> 0 | AK31: =IF(N31>20%,1,0) -> 0 | AL31: =MIN(N31,'Scenario Modelling'!$B$2) -> 0.087 | AM31: =L31*(1+'Scenario Modelling'!$B$3) -> 569.9285 | AN31: =O31*(1+'Scenario Modelling'!$B$4) -> 20.4 | AO31: =AN31*M31*(1-AL31) -> 11767.029 | AP31: =(M31*(1-AL31)-AM31)*AN31 -> 140.48746
A32: ORD-2023-562894 | B32: 44980 | C32: 45010 | D32: Americas | E32: Canada | F32: Montreal | G32: Enterprise | H32: Online | I32: D. Smith | J32: Phones | K32: PHN-4854 | L32: 1242.66 | M32: 1794.07 | N32: 0.089 | O32: 16 | P32: =IF(M32>0,"Valid") -> Valid | Q32: =ABS(M32) -> 1794.07 | R32: =IF(N32>30%,"Excess") -> FALSE | S32: =IF(R32="Excess",30%,N32) -> 0.089 | T32: =(C32-B32) -> 30 | U32: =IF(C32<B32,B32+7,C32) -> 45010 | V32: =(U32-B32) -> 30 | W32: =(Q32*O32*(100-S32)) -> 2867957.2 | X32: =(Q32*O32) -> 28705.12 | Y32: =W32-X32 -> 2839252.1 | Z32: =Y32/W32 -> 0.98999109 | AA32: Feb-2023 | AB32: ="Q"&ROUNDUP(MONTH(B32)/3,0)&"-"&YEAR(B32) -> Q1-2023 | AC32: =D32&" → "&E32&" → "&F32 -> Americas → Canada → Montreal | AD32: =IF(OR(J32="Laptops",J32="Phones"),"Devices",IF(OR(J32="Monitors",J32="Printers"),"Peripherals","Support")) -> Devices | AE32: =IF(B32<=PERCENTILE($B$2:$B$632,0.33),"Low",IF(B32<=PERCENTILE($B$2:$B$632,0.66),"Medium","High")) -> Low | AF32: =UPPER(TRIM(CLEAN(SUBSTITUTE(E32,CHAR(160),"")))) -> CANADA | AG32: =_xlfn.MINIFS($B$2:$B$633,$AF$2:$AF$633,AF32) -> 44928 | AH32: =TEXT(AG32,"MMM-YYYY") -> Jan-2023 | AI32: =EOMONTH(B32,0) -> 44985 | AJ32: =IF(V32<=7,1,0) -> 0 | AK32: =IF(N32>20%,1,0) -> 0 | AL32: =MIN(N32,'Scenario Modelling'!$B$2) -> 0.089 | AM32: =L32*(1+'Scenario Modelling'!$B$3) -> 1429.059 | AN32: =O32*(1+'Scenario Modelling'!$B$4) -> 19.2 | AO32: =AN32*M32*(1-AL32) -> 31380.437 | AP32: =(M32*(1-AL32)-AM32)*AN32 -> 3942.5044
A33: ORD-2025-474710 | B33: 45862 | C33: 45875 | D33: Africa | E33: South Africa | F33: Johannesburg | G33: Education | H33: Marketplace | I33: D. Smith | J33: Networking | K33: NET-7966 | L33: 1463.9 | M33: 2633.02 | N33: 0.084 | O33: 4 | P33: =IF(M33>0,"Valid") -> Valid | Q33: =ABS(M33) -> 2633.02 | R33: =IF(N33>30%,"Excess") -> FALSE | S33: =IF(R33="Excess",30%,N33) -> 0.084 | T33: =(C33-B33) -> 13 | U33: =IF(C33<B33,B33+7,C33) -> 45875 | V33: =(U33-B33) -> 13 | W33: =(Q33*O33*(100-S33)) -> 1052323.3 | X33: =(Q33*O33) -> 10532.08 | Y33: =W33-X33 -> 1041791.2 | Z33: =Y33/W33 -> 0.98999159 | AA33: Jul-2025 | AB33: ="Q"&ROUNDUP(MONTH(B33)/3,0)&"-"&YEAR(B33) -> Q3-2025 | AC33: =D33&" → "&E33&" → "&F33 -> Africa → South Africa → Johannesburg | AD33: =IF(OR(J33="Laptops",J33="Phones"),"Devices",IF(OR(J33="Monitors",J33="Printers"),"Peripherals","Support")) -> Support | AE33: =IF(B33<=PERCENTILE($B$2:$B$632,0.33),"Low",IF(B33<=PERCENTILE($B$2:$B$632,0.66),"Medium","High")) -> High | AF33: =UPPER(TRIM(CLEAN(SUBSTITUTE(E33,CHAR(160),"")))) -> SOUTH AFRICA | AG33: =_xlfn.MINIFS($B$2:$B$633,$AF$2:$AF$633,AF33) -> 44933 | AH33: =TEXT(AG33,"MMM-YYYY") -> Jan-2023 | AI33: =EOMONTH(B33,0) -> 45869 | AJ33: =IF(V33<=7,1,0) -> 0 | AK33: =IF(N33>20%,1,0) -> 0 | AL33: =MIN(N33,'Scenario Modelling'!$B$2) -> 0.084 | AM33: =L33*(1+'Scenario Modelling'!$B$3) -> 1683.485 | AN33: =O33*(1+'Scenario Modelling'!$B$4) -> 4.8 | AO33: =AN33*M33*(1-AL33) -> 11576.862 | AP33: =(M33*(1-AL33)-AM33)*AN33 -> 3496.1343
A34: ORD-2024-629525 | B34: 45400 | C34: 45420 | D34: Europe | E34: United Kingdom | F34: London | G34: Non-Profit | H34: Unknown Channel | I34: D. Smith | J34: Laptops | K34: LAP-9932 | L34: 645.33 | M34: 1321.85 | N34: 0 | O34: 10 | P34: =IF(M34>0,"Valid") -> Valid | Q34: =ABS(M34) -> 1321.85 | R34: =IF(N34>30%,"Excess") -> FALSE | S34: =IF(R34="Excess",30%,N34) -> 0 | T34: =(C34-B34) -> 20 | U34: =IF(C34<B34,B34+7,C34) -> 45420 | V34: =(U34-B34) -> 20 | W34: =(Q34*O34*(100-S34)) -> 1321850 | X34: =(Q34*O34) -> 13218.5 | Y34: =W34-X34 -> 1308631.5 | Z34: =Y34/W34 -> 0.99 | AA34: Apr-2024 | AB34: ="Q"&ROUNDUP(MONTH(B34)/3,0)&"-"&YEAR(B34) -> Q2-2024 | AC34: =D34&" → "&E34&" → "&F34 -> Europe → United Kingdom → London | AD34: =IF(OR(J34="Laptops",J34="Phones"),"Devices",IF(OR(J34="Monitors",J34="Printers"),"Peripherals","Support")) -> Devices | AE34: =IF(B34<=PERCENTILE($B$2:$B$632,0.33),"Low",IF(B34<=PERCENTILE($B$2:$B$632,0.66),"Medium","High")) -> Medium | AF34: =UPPER(TRIM(CLEAN(SUBSTITUTE(E34,CHAR(160),"")))) -> UNITED KINGDOM | AG34: 44945 | AH34: =TEXT(AG34,"MMM-YYYY") -> Jan-2023 | AI34: =EOMONTH(B34,0) -> 45412 | AJ34: =IF(V34<=7,1,0) -> 0 | AK34: =IF(N34>20%,1,0) -> 0 | AL34: =MIN(N34,'Scenario Modelling'!$B$2) -> 0 | AM34: =L34*(1+'Scenario Modelling'!$B$3) -> 742.1295 | AN34: =O34*(1+'Scenario Modelling'!$B$4) -> 12 | AO34: =AN34*M34*(1-AL34) -> 15862.2 | AP34: =(M34*(1-AL34)-AM34)*AN34 -> 6956.646
